{
  "exploitdb": [],
  "itw": [
    {
      "id": "CVE-2022-47515",
      "description": "An issue was discovered in drachtio-server before 0.8.20. It allows remote attackers to cause a denial of service (daemon crash) via a long message in a TCP request that leads to std::length_error.",
      "referenceURL": "https://nvd.nist.gov/vuln/detail/CVE-2022-47515",
      "reportURL": "https://github.com/drachtio/drachtio-server/issues/245",
      "timeStamp": "2022-12-22T18:16:00Z"
    }
  ],
  "trickest": [],
  "nomisec": [],
  "nuclei": [],
  "metasploit": [],
  "holloways": [],
  "openpoc": [
    {
      "cve": "CVE-2022-47515",
      "url": "https://github.com/drachtio/drachtio-server/issues/245",
      "added_at": "2022-12-22T18:16:00Z",
      "score": 0.4,
      "template_for": ""
    }
  ]
}
