{
  "exploitdb": [],
  "itw": [
    {
      "id": "CVE-2022-48560",
      "description": "A use-after-free exists in Python through 3.9 via heappushpop in heapq.",
      "referenceURL": "https://nvd.nist.gov/vuln/detail/CVE-2022-48560",
      "reportURL": "https://bugs.python.org/issue39421",
      "timeStamp": "2023-08-26T02:16:00Z"
    }
  ],
  "trickest": [
    {
      "id": "CVE-2022-48560",
      "url": "https://bugs.python.org/issue39421",
      "added_at": "1970-01-01T00:00:00Z"
    }
  ],
  "nomisec": [],
  "nuclei": [],
  "metasploit": [],
  "holloways": [
    {
      "cve": "CVE-2022-48560",
      "url": "https://www.cve.news/cve-2022-48560/",
      "added_at": "2023-10-23T00:00:00Z",
      "score": 1,
      "template_for": ""
    }
  ],
  "openpoc": [
    {
      "cve": "CVE-2022-48560",
      "url": "https://bugs.python.org/issue39421",
      "added_at": "2023-08-26T02:16:00Z",
      "score": 0,
      "template_for": ""
    },
    {
      "cve": "CVE-2022-48560",
      "url": "https://www.cve.news/cve-2022-48560/",
      "added_at": "2023-10-23T00:00:00Z",
      "score": 1,
      "template_for": ""
    }
  ]
}
