{
  "exploitdb": [],
  "itw": [
    {
      "id": "CVE-2021-45469",
      "description": "In __f2fs_setxattr in fs/f2fs/xattr.c in the Linux kernel through 5.15.11, there is an out-of-bounds memory access when an inode has an invalid last xattr entry.",
      "referenceURL": "https://nvd.nist.gov/vuln/detail/CVE-2021-45469",
      "reportURL": "https://bugzilla.kernel.org/show_bug.cgi?id=215235",
      "timeStamp": "2022-01-04T14:56:00Z"
    },
    {
      "id": "CVE-2021-45469",
      "description": "In __f2fs_setxattr in fs/f2fs/xattr.c in the Linux kernel through 5.15.11, there is an out-of-bounds memory access when an inode has an invalid last xattr entry.",
      "referenceURL": "https://nvd.nist.gov/vuln/detail/CVE-2021-45469",
      "reportURL": "https://git.kernel.org/pub/scm/linux/kernel/git/chao/linux.git/commit/?h=dev\u0026id=5598b24efaf4892741c798b425d543e4bed357a1",
      "timeStamp": "2022-01-04T14:56:00Z"
    }
  ],
  "trickest": [
    {
      "id": "CVE-2021-45469",
      "url": "https://bugzilla.kernel.org/show_bug.cgi?id=215235",
      "added_at": "1970-01-01T00:00:00Z"
    }
  ],
  "nomisec": [],
  "nuclei": [],
  "metasploit": [],
  "holloways": [],
  "openpoc": [
    {
      "cve": "CVE-2021-45469",
      "url": "https://bugzilla.kernel.org/show_bug.cgi?id=215235",
      "added_at": "2022-01-04T14:56:00Z",
      "score": 0,
      "template_for": ""
    },
    {
      "cve": "CVE-2021-45469",
      "url": "https://git.kernel.org/pub/scm/linux/kernel/git/chao/linux.git/commit/?h=dev\u0026id=5598b24efaf4892741c798b425d543e4bed357a1",
      "added_at": "2022-01-04T14:56:00Z",
      "score": 0.4,
      "template_for": ""
    }
  ]
}
